Workbook

Sheet Raw_Sales_Data
A1: Date | B1: Region | C1: Salesperson | D1: Product | E1: Units | F1: Revenue | G1: Target
A2: 45658 | B2: North | C2: Aryan | D2: Mobile | E2: 6 | F2: 116655 | G2: 96475
A3: 45658 | B3: South | C3: Karan | D3: Mobile | E3: 3 | F3: 76829 | G3: 65307
A4: 45658 | B4: South | C4: Lata | D4: Tablet | E4: 2 | F4: 43625 | G4: 36310
A5: 45658 | B5: South | C5: Lata | D5: Monitor | E5: 2 | F5: 43163 | G5: 30975
A6: 45658 | B6: South | C6: Lata | D6: Power Bank | E6: 3 | F6: 51178 | G6: 39633
A7: 45658 | B7: South | C7: Manoj | D7: Mobile | E7: 3 | F7: 75465 | G7: 95614
A8: 45658 | B8: South | C8: Manoj | D8: Power Bank | E8: 2 | F8: 62218 | G8: 66324
A9: 45658 | B9: South | C9: Manoj | D9: Laptop | E9: 3 | F9: 82735 | G9: 106317
A10: 45658 | B10: South | C10: Neha | D10: LED TV | E10: 2 | F10: 44808 | G10: 52253
A11: 45658 | B11: South | C11: -- | D11: Laptop | E11: 3 | F11: 78128 | G11: 90040
A12: 45658 | B12: South | C12: -- | D12: Power Bank | E12: 2 | F12: 57386 | G12: 74328
A13: 45658 | B13: South | C13: om | D13: Mobile | E13: 3 | F13: 67693 | G13: 79782
... A58: 45658 | B58: West | C58: Fahad | D58: Freezer | E58: 4 | F58: 100539 | G58: 75103
A59: 45658 | B59: West | D59: Laptop | E59: 5 | F59: 108058 | G59: 89145
A60: 45658 | B60: West | D60: Power Bank | E60: 2 | F60: 80872 | G60: 69325
A61: 45658 | B61: West | D61: Mobile | E61: 4 | F61: 94495 | G61: 73481
A62: 45659 | B62: South | C62: Neha | D62: Power Bank | E62: 2 | F62: 63627 | G62: 78658
A63: 45659 | B63: South | C63: Om | D63: Freezer | E63: 4 | F63: 88175 | G63: 111889
A64: 45659 | B64: South | C64: Neha | D64: Power Bank | E64: 2 | F64: 56631 | G64: 72238
A65: 45659 | B65: South | C65: Om | D65: Headphones | E65: 2 | F65: 44567 | G65: 51570
A66: 45659 | B66: South | C66: Neha | D66: Tablet | E66: 2 | F66: 45470 | G66: 49504
A67: 45659 | B67: South | C67: Om | D67: Tablet | E67: 2 | F67: 42550 | G67: 52790
A68: 45659 | B68: South | C68: Neha | D68: Freezer | E68: 3 | F68: 91124 | G68: 111304
A69: 45659 | B69: South | C69: Lata | D69: Tablet | E69: 2 | F69: 43973 | G69: 32473
A70: 45659 | B70: South | C70: Manoj | D70: Laptop | E70: 3 | F70: 89539 | G70: 113273
A71: 45659 | B71: South | C71: Manoj | D71: Freezer | E71: 4 | F71: 83360 | G71: 100347
A72: 45659 | B72: South | C72: Lata | D72: Monitor | E72: 2 | F72: 39060 | G72: 31724
A73: 45659 | B73: South | C73: Lata | D73: Freezer | E73: 3 | F73: 98314 | G73: 68943
... A88: 45659 | B88: East | C88: Rohan | D88: Power Bank | E88: 2 | F88: 53271 | G88: 66345
A89: 45659 | B89: East | D89: Tablet | E89: 1 | F89: 34577 | G89: 38437
A90: 45659 | B90: East | D90: LED TV | E90: 2 | F90: 48872 | G90: 57313
A91: 45659 | B91: East | C91: Taniya | D91: Freezer | E91: 1 | F91: 22638 | G91: 20887
A92: 45659 | B92: East | D92: Freezer | E92: 1 | F92: 27380 | G92: 23183
A93: 45659 | B93: East | D93: LED TV | E93: 2 | F93: 48264 | G93: 40053
A94: 45659 | B94: East | D94: Mobile | E94: 3 | F94: 74771 | G94: 63982
A95: 45659 | B95: East | C95: Taniya | D95: Power Bank | E95: 2 | F95: 49156 | G95: 38324
A96: 45659 | B96: East | C96: Priya | D96: Headphones | E96: 1 | F96: 26553 | G96: 22260
A97: 45659 | B97: South | C97: Karan | D97: Power Bank | E97: 3 | F97: 64495 | G97: 47705
A98: 45659 | B98: West | C98: Gita | D98: Power Bank | E98: 3 | F98: 82065 | G98: 73569
...

Sheet Cleaned_Data
A1: Date | B1: Month | C1: Region | D1: Salesperson | E1: Product | F1: Units | G1: Revenue | H1: Revenue Category | I1: Target | J1: Achievement % | K1: Status
A2: 45658 | B2: =TEXT(A2,"MMM") -> Jan | C2: North | D2: Aryan | E2: Mobile | F2: 6 | G2: 116655 | H2: =IFS( G2 > 90000, "Very High Range", AND(G2 > 70000, G2 < 90000), "High Range", AND(G2 > 50000, G2 < 70000), "Medium Range", TRUE, "Base Range" ) -> Very High Range | I2: 96475 | J2: =G2/I2 -> 1.2091734 | K2: =IF(J2>100%, "Over Achived", "Target Not Meet") -> Over Achived
A3: 45658 | B3: =TEXT(A3,"MMM") -> Jan | C3: South | D3: Karan | E3: Mobile | F3: 3 | G3: 76829 | H3: =IFS( G3 > 90000, "Very High Range", AND(G3 > 70000, G3 < 90000), "High Range", AND(G3 > 50000, G3 < 70000), "Medium Range", TRUE, "Base Range" ) -> High Range | I3: 65307 | J3: =G3/I3 -> 1.1764283 | K3: =IF(J3>100%, "Over Achived", "Target Not Meet") -> Over Achived
A4: 45658 | B4: =TEXT(A4,"MMM") -> Jan | C4: South | D4: Lata | E4: Tablet | F4: 2 | G4: 43625 | H4: =IFS( G4 > 90000, "Very High Range", AND(G4 > 70000, G4 < 90000), "High Range", AND(G4 > 50000, G4 < 70000), "Medium Range", TRUE, "Base Range" ) -> Base Range | I4: 36310 | J4: =G4/I4 -> 1.2014597 | K4: =IF(J4>100%, "Over Achived", "Target Not Meet") -> Over Achived
A5: 45658 | B5: =TEXT(A5,"MMM") -> Jan | C5: South | D5: Lata | E5: Monitor | F5: 2 | G5: 43163 | H5: =IFS( G5 > 90000, "Very High Range", AND(G5 > 70000, G5 < 90000), "High Range", AND(G5 > 50000, G5 < 70000), "Medium Range", TRUE, "Base Range" ) -> Base Range | I5: 30975 | J5: =G5/I5 -> 1.3934786 | K5: =IF(J5>100%, "Over Achived", "Target Not Meet") -> Over Achived
A6: 45658 | B6: =TEXT(A6,"MMM") -> Jan | C6: South | D6: Lata | E6: Power Bank | F6: 3 | G6: 51178 | H6: =IFS( G6 > 90000, "Very High Range", AND(G6 > 70000, G6 < 90000), "High Range", AND(G6 > 50000, G6 < 70000), "Medium Range", TRUE, "Base Range" ) -> Medium Range | I6: 39633 | J6: =G6/I6 -> 1.2912977 | K6: =IF(J6>100%, "Over Achived", "Target Not Meet") -> Over Achived
A7: 45658 | B7: =TEXT(A7,"MMM") -> Jan | C7: South | D7: Manoj | E7: Mobile | F7: 3 | G7: 75465 | H7: =IFS( G7 > 90000, "Very High Range", AND(G7 > 70000, G7 < 90000), "High Range", AND(G7 > 50000, G7 < 70000), "Medium Range", TRUE, "Base Range" ) -> High Range | I7: 95614 | J7: =G7/I7 -> 0.78926726 | K7: =IF(J7>100%, "Over Achived", "Target Not Meet") -> Target Not Meet
A8: 45658 | B8: =TEXT(A8,"MMM") -> Jan | C8: South | D8: Manoj | E8: Power Bank | F8: 2 | G8: 62218 | H8: =IFS( G8 > 90000, "Very High Range", AND(G8 > 70000, G8 < 90000), "High Range", AND(G8 > 50000, G8 < 70000), "Medium Range", TRUE, "Base Range" ) -> Medium Range | I8: 66324 | J8: =G8/I8 -> 0.93809179 | K8: =IF(J8>100%, "Over Achived", "Target Not Meet") -> Target Not Meet
A9: 45658 | B9: =TEXT(A9,"MMM") -> Jan | C9: South | D9: Manoj | E9: Laptop | F9: 3 | G9: 82735 | H9: =IFS( G9 > 90000, "Very High Range", AND(G9 > 70000, G9 < 90000), "High Range", AND(G9 > 50000, G9 < 70000), "Medium Range", TRUE, "Base Range" ) -> High Range | I9: 106317 | J9: =G9/I9 -> 0.77819163 | K9: =IF(J9>100%, "Over Achived", "Target Not Meet") -> Target Not Meet
A10: 45658 | B10: =TEXT(A10,"MMM") -> Jan | C10: South | D10: Neha | E10: LED TV | F10: 2 | G10: 44808 | H10: =IFS( G10 > 90000, "Very High Range", AND(G10 > 70000, G10 < 90000), "High Range", AND(G10 > 50000, G10 < 70000), "Medium Range", TRUE, "Base Range" ) -> Base Range | I10: 52253 | J10: =G10/I10 -> 0.85752014 | K10: =IF(J10>100%, "Over Achived", "Target Not Meet") -> Target Not Meet
A11: 45658 | B11: =TEXT(A11,"MMM") -> Jan | C11: South | D11: Neha | E11: Laptop | F11: 3 | G11: 78128 | H11: =IFS( G11 > 90000, "Very High Range", AND(G11 > 70000, G11 < 90000), "High Range", AND(G11 > 50000, G11 < 70000), "Medium Range", TRUE, "Base Range" ) -> High Range | I11: 90040 | J11: =G11/I11 -> 0.86770324 | K11: =IF(J11>100%, "Over Achived", "Target Not Meet") -> Target Not Meet
A12: 45658 | B12: =TEXT(A12,"MMM") -> Jan | C12: South | D12: Neha | E12: Power Bank | F12: 2 | G12: 57386 | H12: =IFS( G12 > 90000, "Very High Range", AND(G12 > 70000, G12 < 90000), "High Range", AND(G12 > 50000, G12 < 70000), "Medium Range", TRUE, "Base Range" ) -> Medium Range | I12: 74328 | J12: =G12/I12 -> 0.77206436 | K12: =IF(J12>100%, "Over Achived", "Target Not Meet") -> Target Not Meet
A13: 45658 | B13: =TEXT(A13,"MMM") -> Jan | C13: South | D13: Om | E13: Mobile | F13: 3 | G13: 67693 | H13: =IFS( G13 > 90000, "Very High Range", AND(G13 > 70000, G13 < 90000), "High Range", AND(G13 > 50000, G13 < 70000), "Medium Range", TRUE, "Base Range" ) -> Medium Range | I13: 79782 | J13: =G13/I13 -> 0.84847459 | K13: =IF(J13>100%, "Over Achived", "Target Not Meet") -> Target Not Meet
... A4167: 45717 | B4167: =TEXT(A4167,"MMM") -> Mar | C4167: South | D4167: Om | E4167: Tablet | F4167: 2 | G4167: 38935 | H4167: =IFS( G4167 > 90000, "Very High Range", AND(G4167 > 70000, G4167 < 90000), "High Range", AND(G4167 > 50000, G4167 < 70000), "Medium Range", TRUE, "Base Range" ) -> Base Range | I4167: 42098 | J4167: =G4167/I4167 -> 0.92486579 | K4167: =IF(J4167>100%, "Over Achived", "Target Not Meet") -> Target Not Meet
A4168: 45717 | B4168: =TEXT(A4168,"MMM") -> Mar | C4168: South | D4168: Om | E4168: Laptop | F4168: 3 | G4168: 74789 | H4168: =IFS( G4168 > 90000, "Very High Range", AND(G4168 > 70000, G4168 < 90000), "High Range", AND(G4168 > 50000, G4168 < 70000), "Medium Range", TRUE, "Base Range" ) -> High Range | I4168: 81794 | J4168: =G4168/I4168 -> 0.91435802 | K4168: =IF(J4168>100%, "Over Achived", "Target Not Meet") -> Target Not Meet | M4168: {=INDEX(D:D, MATCH(MAX(G:G),G:G,0))} -> Bhavin
A4169: 45717 | B4169: =TEXT(A4169,"MMM") -> Mar | C4169: South | D4169: Om | E4169: Mobile | F4169: 3 | G4169: 79646 | H4169: =IFS( G4169 > 90000, "Very High Range", AND(G4169 > 70000, G4169 < 90000), "High Range", AND(G4169 > 50000, G4169 < 70000), "Medium Range", TRUE, "Base Range" ) -> High Range | I4169: 85609 | J4169: =G4169/I4169 -> 0.93034611 | K4169: =IF(J4169>100%, "Over Achived", "Target Not Meet") -> Target Not Meet
A4170: 45717 | B4170: =TEXT(A4170,"MMM") -> Mar | C4170: South | D4170: Neha | E4170: Mobile | F4170: 3 | G4170: 86356 | H4170: =IFS( G4170 > 90000, "Very High Range", AND(G4170 > 70000, G4170 < 90000), "High Range", AND(G4170 > 50000, G4170 < 70000), "Medium Range", TRUE, "Base Range" ) -> High Range | I4170: 95674 | J4170: =G4170/I4170 -> 0.90260677 | K4170: =IF(J4170>100%, "Over Achived", "Target Not Meet") -> Target Not Meet
A4171: 45717 | B4171: =TEXT(A4171,"MMM") -> Mar | C4171: South | D4171: Neha | E4171: Mobile | F4171: 3 | G4171: 66759 | H4171: =IFS( G4171 > 90000, "Very High Range", AND(G4171 > 70000, G4171 < 90000), "High Range", AND(G4171 > 50000, G4171 < 70000), "Medium Range", TRUE, "Base Range" ) -> Medium Range | I4171: 79769 | J4171: =G4171/I4171 -> 0.83690406 | K4171: =IF(J4171>100%, "Over Achived", "Target Not Meet") -> Target Not Meet
A4172: 45717 | B4172: =TEXT(A4172,"MMM") -> Mar | C4172: South | D4172: Manoj | E4172: Tablet | F4172: 1 | G4172: 37049 | H4172: =IFS( G4172 > 90000, "Very High Range", AND(G4172 > 70000, G4172 < 90000), "High Range", AND(G4172 > 50000, G4172 < 70000), "Medium Range", TRUE, "Base Range" ) -> Base Range | I4172: 43652 | J4172: =G4172/I4172 -> 0.84873545 | K4172: =IF(J4172>100%, "Over Achived", "Target Not Meet") -> Target Not Meet
A4173: 45717 | B4173: =TEXT(A4173,"MMM") -> Mar | C4173: South | D4173: Manoj | E4173: LED TV | F4173: 2 | G4173: 53718 | H4173: =IFS( G4173 > 90000, "Very High Range", AND(G4173 > 70000, G4173 < 90000), "High Range", AND(G4173 > 50000, G4173 < 70000), "Medium Range", TRUE, "Base Range" ) -> Medium Range | I4173: 62110 | J4173: =G4173/I4173 -> 0.86488488 | K4173: =IF(J4173>100%, "Over Achived", "Target Not Meet") -> Target Not Meet
A4174: 45717 | B4174: =TEXT(A4174,"MMM") -> Mar | C4174: South | D4174: Lata | E4174: Laptop | F4174: 3 | G4174: 80825 | H4174: =IFS( G4174 > 90000, "Very High Range", AND(G4174 > 70000, G4174 < 90000), "High Range", AND(G4174 > 50000, G4174 < 70000), "Medium Range", TRUE, "Base Range" ) -> High Range | I4174: 63790 | J4174: =G4174/I4174 -> 1.2670481 | K4174: =IF(J4174>100%, "Over Achived", "Target Not Meet") -> Over Achived
A4175: 45717 | B4175: =TEXT(A4175,"MMM") -> Mar | C4175: South | D4175: Manoj | E4175: Tablet | F4175: 2 | G4175: 47554 | H4175: =IFS( G4175 > 90000, "Very High Range", AND(G4175 > 70000, G4175 < 90000), "High Range", AND(G4175 > 50000, G4175 < 70000), "Medium Range", TRUE, "Base Range" ) -> Base Range | I4175: 59858 | J4175: =G4175/I4175 -> 0.79444686 | K4175: =IF(J4175>100%, "Over Achived", "Target Not Meet") -> Target Not Meet
A4176: 45717 | B4176: =TEXT(A4176,"MMM") -> Mar | C4176: South | D4176: Lata | E4176: Tablet | F4176: 1 | G4176: 45829 | H4176: =IFS( G4176 > 90000, "Very High Range", AND(G4176 > 70000, G4176 < 90000), "High Range", AND(G4176 > 50000, G4176 < 70000), "Medium Range", TRUE, "Base Range" ) -> Base Range | I4176: 32548 | J4176: =G4176/I4176 -> 1.4080435 | K4176: =IF(J4176>100%, "Over Achived", "Target Not Meet") -> Over Achived
A4177: 45717 | B4177: =TEXT(A4177,"MMM") -> Mar | C4177: South | D4177: Lata | E4177: Headphones | F4177: 1 | G4177: 31182 | H4177: =IFS( G4177 > 90000, "Very High Range", AND(G4177 > 70000, G4177 < 90000), "High Range", AND(G4177 > 50000, G4177 < 70000), "Medium Range", TRUE, "Base Range" ) -> Base Range | I4177: 29284 | J4177: =G4177/I4177 -> 1.0648135 | K4177: =IF(J4177>100%, "Over Achived", "Target Not Meet") -> Over Achived
A4178: 45717 | B4178: =TEXT(A4178,"MMM") -> Mar | C4178: South | D4178: Lata | E4178: Laptop | F4178: 3 | G4178: 66226 | H4178: =IFS( G4178 > 90000, "Very High Range", AND(G4178 > 70000, G4178 < 90000), "High Range", AND(G4178 > 50000, G4178 < 70000), "Medium Range", TRUE, "Base Range" ) -> Medium Range | I4178: 53447 | J4178: =G4178/I4178 -> 1.2390967 | K4178: =IF(J4178>100%, "Over Achived", "Target Not Meet") -> Over Achived
A4179: 45717 | B4179: =TEXT(A4179,"MMM") -> Mar | C4179: East | D4179: Priya | E4179: Laptop | F4179: 2 | G4179: 51239 | H4179: =IFS( G4179 > 90000, "Very High Range", AND(G4179 > 70000, G4179 < 90000), "High Range", AND(G4179 > 50000, G4179 < 70000), "Medium Range", TRUE, "Base Range" ) -> Medium Range | I4179: 45353 | J4179: =G4179/I4179 -> 1.1297819 | K4179: =IF(J4179>100%, "Over Achived", "Target Not Meet") -> Over Achived
A4180: 45717 | B4180: =TEXT(A4180,"MMM") -> Mar | C4180: South | D4180: Manoj | E4180: Headphones | F4180: 1 | G4180: 38120 | H4180: =IFS( G4180 > 90000, "Very High Range", AND(G4180 > 70000, G4180 < 90000), "High Range", AND(G4180 > 50000, G4180 < 70000), "Medium Range", TRUE, "Base Range" ) -> Base Range | I4180: 40565 | J4180: =G4180/I4180 -> 0.93972637 | K4180: =IF(J4180>100%, "Over Achived", "Target Not Meet") -> Target Not Meet
... A12644: 45838 | B12644: =TEXT(A12644,"MMM") -> Jun | C12644: East | D12644: Tina | E12644: Freezer | F12644: 1 | G12644: 36124 | H12644: =IFS( G12644 > 90000, "Very High Range", AND(G12644 > 70000, G12644 < 90000), "High Range", AND(G12644 > 50000, G12644 < 70000), "Medium Range", TRUE, "Base Range" ) -> Base Range | I12644: 41464 | J12644: =G12644/I12644 -> 0.87121358 | K12644: =IF(J12644>100%, "Over Achived", "Target Not Meet") -> Target Not Meet

Sheet Pivot_Tabs
E7: Prepare the Data Sheet
D11: Total Revenue by Region : | G11: Slesperson by Achivement - Sales : | K11: Salesperson by Revenue :
D20: Total Revenue by Product :
D32: Distrubution of Status :
G35: Distrubution of Product :
D39: Total Revenue by Month :
G57: =IFERROR(__xludf.DUMMYFUNCTION("QUERY(Cleaned_Data!1:12644, ""SELECT C, E, SUM(G) GROUP BY C, E ORDER BY C, SUM(G) DESC LABEL SUM(G) 'Revenue'"" ) "),"Region") -> Region | H57: =IFERROR(__xludf.DUMMYFUNCTION("""COMPUTED_VALUE"""),"Product") -> Product | I57: =IFERROR(__xludf.DUMMYFUNCTION("""COMPUTED_VALUE"""),"Revenue") -> Revenue
G58: =IFERROR(__xludf.DUMMYFUNCTION("""COMPUTED_VALUE"""),"East") -> East | H58: =IFERROR(__xludf.DUMMYFUNCTION("""COMPUTED_VALUE"""),"Mobile") -> Mobile | I58: =IFERROR(__xludf.DUMMYFUNCTION("""COMPUTED_VALUE"""),2.5009763E7) -> 25009763
G59: =IFERROR(__xludf.DUMMYFUNCTION("""COMPUTED_VALUE"""),"East") -> East | H59: =IFERROR(__xludf.DUMMYFUNCTION("""COMPUTED_VALUE"""),"Laptop") -> Laptop | I59: =IFERROR(__xludf.DUMMYFUNCTION("""COMPUTED_VALUE"""),2.2252302E7) -> 22252302
G60: =IFERROR(__xludf.DUMMYFUNCTION("""COMPUTED_VALUE"""),"East") -> East | H60: =IFERROR(__xludf.DUMMYFUNCTION("""COMPUTED_VALUE"""),"Power Bank") -> Power Bank | I60: =IFERROR(__xludf.DUMMYFUNCTION("""COMPUTED_VALUE"""),1.5642756E7) -> 15642756
G61: =IFERROR(__xludf.DUMMYFUNCTION("""COMPUTED_VALUE"""),"East") -> East | H61: =IFERROR(__xludf.DUMMYFUNCTION("""COMPUTED_VALUE"""),"LED TV") -> LED TV | I61: =IFERROR(__xludf.DUMMYFUNCTION("""COMPUTED_VALUE"""),1.4666188E7) -> 14666188
G62: =IFERROR(__xludf.DUMMYFUNCTION("""COMPUTED_VALUE"""),"East") -> East | H62: =IFERROR(__xludf.DUMMYFUNCTION("""COMPUTED_VALUE"""),"Tablet") -> Tablet | I62: =IFERROR(__xludf.DUMMYFUNCTION("""COMPUTED_VALUE"""),1.3870756E7) -> 13870756
G63: =IFERROR(__xludf.DUMMYFUNCTION("""COMPUTED_VALUE"""),"East") -> East | H63: =IFERROR(__xludf.DUMMYFUNCTION("""COMPUTED_VALUE"""),"Monitor") -> Monitor | I63: =IFERROR(__xludf.DUMMYFUNCTION("""COMPUTED_VALUE"""),1.1500556E7) -> 11500556
G64: =IFERROR(__xludf.DUMMYFUNCTION("""COMPUTED_VALUE"""),"East") -> East | H64: =IFERROR(__xludf.DUMMYFUNCTION("""COMPUTED_VALUE"""),"Headphones") -> Headphones | I64: =IFERROR(__xludf.DUMMYFUNCTION("""COMPUTED_VALUE"""),9566030.0) -> 9566030
G65: =IFERROR(__xludf.DUMMYFUNCTION("""COMPUTED_VALUE"""),"East") -> East | H65: =IFERROR(__xludf.DUMMYFUNCTION("""COMPUTED_VALUE"""),"Freezer") -> Freezer | I65: =IFERROR(__xludf.DUMMYFUNCTION("""COMPUTED_VALUE"""),8984093.0) -> 8984093
G66: =IFERROR(__xludf.DUMMYFUNCTION("""COMPUTED_VALUE"""),"North") -> North | H66: =IFERROR(__xludf.DUMMYFUNCTION("""COMPUTED_VALUE"""),"Power Bank") -> Power Bank | I66: =IFERROR(__xludf.DUMMYFUNCTION("""COMPUTED_VALUE"""),8.0829914E7) -> 80829914
G67: =IFERROR(__xludf.DUMMYFUNCTION("""COMPUTED_VALUE"""),"North") -> North | H67: =IFERROR(__xludf.DUMMYFUNCTION("""COMPUTED_VALUE"""),"Mobile") -> Mobile | I67: =IFERROR(__xludf.DUMMYFUNCTION("""COMPUTED_VALUE"""),5.8323791E7) -> 58323791
G68: =IFERROR(__xludf.DUMMYFUNCTION("""COMPUTED_VALUE"""),"North") -> North | H68: =IFERROR(__xludf.DUMMYFUNCTION("""COMPUTED_VALUE"""),"Laptop") -> Laptop | I68: =IFERROR(__xludf.DUMMYFUNCTION("""COMPUTED_VALUE"""),5.3903489E7) -> 53903489
G69: =IFERROR(__xludf.DUMMYFUNCTION("""COMPUTED_VALUE"""),"North") -> North | H69: =IFERROR(__xludf.DUMMYFUNCTION("""COMPUTED_VALUE"""),"LED TV") -> LED TV | I69: =IFERROR(__xludf.DUMMYFUNCTION("""COMPUTED_VALUE"""),3.6982395E7) -> 36982395
G70: =IFERROR(__xludf.DUMMYFUNCTION("""COMPUTED_VALUE"""),"North") -> North | H70: =IFERROR(__xludf.DUMMYFUNCTION("""COMPUTED_VALUE"""),"Tablet") -> Tablet | I70: =IFERROR(__xludf.DUMMYFUNCTION("""COMPUTED_VALUE"""),3.0143804E7) -> 30143804
G71: =IFERROR(__xludf.DUMMYFUNCTION("""COMPUTED_VALUE"""),"North") -> North | H71: =IFERROR(__xludf.DUMMYFUNCTION("""COMPUTED_VALUE"""),"Monitor") -> Monitor | I71: =IFERROR(__xludf.DUMMYFUNCTION("""COMPUTED_VALUE"""),2.639806E7) -> 26398060
G72: =IFERROR(__xludf.DUMMYFUNCTION("""COMPUTED_VALUE"""),"North") -> North | H72: =IFERROR(__xludf.DUMMYFUNCTION("""COMPUTED_VALUE"""),"Headphones") -> Headphones | I72: =IFERROR(__xludf.DUMMYFUNCTION("""COMPUTED_VALUE"""),2.3407452E7) -> 23407452
G73: =IFERROR(__xludf.DUMMYFUNCTION("""COMPUTED_VALUE"""),"North") -> North | H73: =IFERROR(__xludf.DUMMYFUNCTION("""COMPUTED_VALUE"""),"Freezer") -> Freezer | I73: =IFERROR(__xludf.DUMMYFUNCTION("""COMPUTED_VALUE"""),2.1656634E7) -> 21656634
G74: =IFERROR(__xludf.DUMMYFUNCTION("""COMPUTED_VALUE"""),"South") -> South | H74: =IFERROR(__xludf.DUMMYFUNCTION("""COMPUTED_VALUE"""),"Mobile") -> Mobile | I74: =IFERROR(__xludf.DUMMYFUNCTION("""COMPUTED_VALUE"""),3.1667754E7) -> 31667754
G75: =IFERROR(__xludf.DUMMYFUNCTION("""COMPUTED_VALUE"""),"South") -> South | H75: =IFERROR(__xludf.DUMMYFUNCTION("""COMPUTED_VALUE"""),"Laptop") -> Laptop | I75: =IFERROR(__xludf.DUMMYFUNCTION("""COMPUTED_VALUE"""),3.1125119E7) -> 31125119
G76: =IFERROR(__xludf.DUMMYFUNCTION("""COMPUTED_VALUE"""),"South") -> South | H76: =IFERROR(__xludf.DUMMYFUNCTION("""COMPUTED_VALUE"""),"Power Bank") -> Power Bank | I76: =IFERROR(__xludf.DUMMYFUNCTION("""COMPUTED_VALUE"""),2.2814811E7) -> 22814811
G77: =IFERROR(__xludf.DUMMYFUNCTION("""COMPUTED_VALUE"""),"South") -> South | H77: =IFERROR(__xludf.DUMMYFUNCTION("""COMPUTED_VALUE"""),"LED TV") -> LED TV | I77: =IFERROR(__xludf.DUMMYFUNCTION("""COMPUTED_VALUE"""),2.1219126E7) -> 21219126
G78: =IFERROR(__xludf.DUMMYFUNCTION("""COMPUTED_VALUE"""),"South") -> South | H78: =IFERROR(__xludf.DUMMYFUNCTION("""COMPUTED_VALUE"""),"Freezer") -> Freezer | I78: =IFERROR(__xludf.DUMMYFUNCTION("""COMPUTED_VALUE"""),1.7302811E7) -> 17302811
G79: =IFERROR(__xludf.DUMMYFUNCTION("""COMPUTED_VALUE"""),"South") -> South | H79: =IFERROR(__xludf.DUMMYFUNCTION("""COMPUTED_VALUE"""),"Tablet") -> Tablet | I79: =IFERROR(__xludf.DUMMYFUNCTION("""COMPUTED_VALUE"""),1.662106E7) -> 16621060
G80: =IFERROR(__xludf.DUMMYFUNCTION("""COMPUTED_VALUE"""),"South") -> South | H80: =IFERROR(__xludf.DUMMYFUNCTION("""COMPUTED_VALUE"""),"Monitor") -> Monitor | I80: =IFERROR(__xludf.DUMMYFUNCTION("""COMPUTED_VALUE"""),1.4371266E7) -> 14371266
G81: =IFERROR(__xludf.DUMMYFUNCTION("""COMPUTED_VALUE"""),"South") -> South | H81: =IFERROR(__xludf.DUMMYFUNCTION("""COMPUTED_VALUE"""),"Headphones") -> Headphones | I81: =IFERROR(__xludf.DUMMYFUNCTION("""COMPUTED_VALUE"""),1.4029167E7) -> 14029167
G82: =IFERROR(__xludf.DUMMYFUNCTION("""COMPUTED_VALUE"""),"West") -> West | H82: =IFERROR(__xludf.DUMMYFUNCTION("""COMPUTED_VALUE"""),"Mobile") -> Mobile | I82: =IFERROR(__xludf.DUMMYFUNCTION("""COMPUTED_VALUE"""),4.2995523E7) -> 42995523
G83: =IFERROR(__xludf.DUMMYFUNCTION("""COMPUTED_VALUE"""),"West") -> West | H83: =IFERROR(__xludf.DUMMYFUNCTION("""COMPUTED_VALUE"""),"Laptop") -> Laptop | I83: =IFERROR(__xludf.DUMMYFUNCTION("""COMPUTED_VALUE"""),3.83024E7) -> 38302400
G84: =IFERROR(__xludf.DUMMYFUNCTION("""COMPUTED_VALUE"""),"West") -> West | H84: =IFERROR(__xludf.DUMMYFUNCTION("""COMPUTED_VALUE"""),"Power Bank") -> Power Bank | I84: =IFERROR(__xludf.DUMMYFUNCTION("""COMPUTED_VALUE"""),3.1970564E7) -> 31970564
G85: =IFERROR(__xludf.DUMMYFUNCTION("""COMPUTED_VALUE"""),"West") -> West | H85: =IFERROR(__xludf.DUMMYFUNCTION("""COMPUTED_VALUE"""),"LED TV") -> LED TV | I85: =IFERROR(__xludf.DUMMYFUNCTION("""COMPUTED_VALUE"""),2.8449967E7) -> 28449967
G86: =IFERROR(__xludf.DUMMYFUNCTION("""COMPUTED_VALUE"""),"West") -> West | H86: =IFERROR(__xludf.DUMMYFUNCTION("""COMPUTED_VALUE"""),"Freezer") -> Freezer | I86: =IFERROR(__xludf.DUMMYFUNCTION("""COMPUTED_VALUE"""),2.5247984E7) -> 25247984
G87: =IFERROR(__xludf.DUMMYFUNCTION("""COMPUTED_VALUE"""),"West") -> West | H87: =IFERROR(__xludf.DUMMYFUNCTION("""COMPUTED_VALUE"""),"Monitor") -> Monitor | I87: =IFERROR(__xludf.DUMMYFUNCTION("""COMPUTED_VALUE"""),2.3145924E7) -> 23145924
G88: =IFERROR(__xludf.DUMMYFUNCTION("""COMPUTED_VALUE"""),"West") -> West | H88: =IFERROR(__xludf.DUMMYFUNCTION("""COMPUTED_VALUE"""),"Tablet") -> Tablet | I88: =IFERROR(__xludf.DUMMYFUNCTION("""COMPUTED_VALUE"""),2.2930816E7) -> 22930816
G89: =IFERROR(__xludf.DUMMYFUNCTION("""COMPUTED_VALUE"""),"West") -> West | H89: =IFERROR(__xludf.DUMMYFUNCTION("""COMPUTED_VALUE"""),"Headphones") -> Headphones | I89: =IFERROR(__xludf.DUMMYFUNCTION("""COMPUTED_VALUE"""),1.8551527E7) -> 18551527

Sheet Dashboard
G4: - : Sales Dashboard : -
F9: Total Revenue :- | I9: Total Target :- | L9: Overall Achievement % :- | O9: Total Units Sold :-
F10: =SUM(Cleaned_Data!G:G) -> 853883802 | I10: =SUM(Cleaned_Data!I:I) -> 795828563 | L10: =F10/I10 -> 1.0729494 | O10: =COUNTA(Sales_Data[Units]) -> 12643

Sheet MIS_Report
H3: ABC Pvt Ltd Sales MIS Report
I8: Prepared by - Anirudha Das Date : 01 July 2025
D18: Total Revenue | G18: Total Target | J18: Ovrall Achievement % | M18: Total Units Sold | P18: Number of Salesperson
D20: =Dashboard!F10 -> 853883802 | G20: =Dashboard!I10 -> 795828563 | J20: =Dashboard!L10 -> 1.0729494 | M20: =Dashboard!O10 -> 12643 | P20: =IFERROR(__xludf.DUMMYFUNCTION("COUNTUNIQUE(Sales_Data[Salesperson])"),20.0) -> 20
C24: Top and Lowest Performer Region :- | G24: {=INDEX(Pivot_Tabs!D13:E16, MATCH(MAX(Pivot_Tabs!E13:E16), Pivot_Tabs!E13:E16, 0))} -> North | H24: 331645539 | J24: {=INDEX(Pivot_Tabs!D13:E16, MATCH(MIN(Pivot_Tabs!E13:E16), Pivot_Tabs!E13:E16, 0))} -> East | K24: 121492444
C26: Top and Lowest Performer Salesperson :- | G26: {=INDEX(Pivot_Tabs!K13:L32, MATCH(MAX(Pivot_Tabs!L13:L32), Pivot_Tabs!L13:L32, 0))} -> Deepak | H26: 68853766 | J26: {=INDEX(Pivot_Tabs!K13:L32, MATCH(MIN(Pivot_Tabs!L13:L32), Pivot_Tabs!L13:L32, 0))} -> Sneha | K26: 23779424
C28: Avg. Sales per Salesperson :- | G28: =AVERAGE(Pivot_Tabs!L13:L32) -> 42694190
C30: Avg. Target per Salesperson :- | G30: =AVERAGE(Pivot_Tabs!I13:I32) -> 39791428
C32: Product with Most Units Sold :- | G32: {=INDEX(Pivot_Tabs!G37:H44, MATCH(MAX(Pivot_Tabs!H37:H44), Pivot_Tabs!H37:H44, 0))} -> Mobile | H32: 1639
C34: Product with Highest Revenue :- | G34: {=INDEX(Pivot_Tabs!D22:E29, MATCH(MAX(Pivot_Tabs!E22:E29), Pivot_Tabs!E22:E29, 0))} -> Mobile | H34: 157996831
C39: Performance Insight :-
C41: Actual average sales per salesperson exceeded the average projected target, resulting in an achievement level of 107.29%. This reflects strong sales productivity and indicates that the current target levels were effectively met and surpassed during the reporting period.
C45: The North region emerged as the top performing region in terms of overall sales performance, while the East region recorded the lowest performance during the reporting period.
C49: Performance analysis indicates that Deepak achieved the highest total revenue among all salespersons, demonstrating strong sales effectiveness, whereas Sneha generated the lowest total revenue and may require additional support or performance improvement measures.
C53: Analysis shows that the Mobile product achieved the highest number of units sold as well as the highest revenue contribution, indicating strong customer demand and consistent sales performance within this category.
C57: Revenue analysis shows that June generated the maximum sales revenue, with subsequent performance levels observed in January, February, and March respectively. This trend highlights stronger sales momentum toward the start-year period.
C61: Fahad, Priya, Deepak, Bhavin, and Taniya demonstrated outstanding sales performance by surpassing their respective targets, positioning them among the top five overachievers for the period under review.
C65: Analysis indicates that the highest revenue-generating product differs across regions, with region like East, West and South lead by Mobile and North lead by Power Bank. This demonstrating a distinct product preference based on sales performance during the reporting period.
